Workbook

Sheet Overview
A1: Enterprise IT Service Desk & Identity Access Management Simulation
A2: (ServiceNow | Active Directory | Azure AD | Okta | Intune | IT Support)
A4: Project Purpose | B4: Simulates a real company L1 service desk environment covering incidents, access requests, authentication issues, endpoint compliance checks, escalations, SLA tracking, and knowledge-base documentation.
A6: Workbook Contents
A7: Tickets | B7: 200 simulated incidents with categories, priorities, SLA targets, escalations, and resolutions.
A8: User_Access_Requests | B8: 80 onboarding/offboarding and access-management requests mapped to AD, Azure AD, Okta, SharePoint, and VPN.
A9: Escalation_Cases | B9: Subset of complex incidents escalated to L2/L3 teams with business impact and handoff notes.
A10: Knowledge_Base | B10: 22 common L1 solutions for first-call resolution and self-service support.
A11: SLA_Dashboard | B11: Formula-driven KPI sheet with charts for SLA, priority mix, category mix, and FCR.
A14: Mapped Job Requirements
A15: Incident logging & ticket handling | B15: Tickets / SLA_Dashboard
A16: User lifecycle operations | B16: User_Access_Requests
A17: Active Directory / Azure AD support | B17: Tickets / User_Access_Requests
A18: Okta MFA & access troubleshooting | B18: Tickets / Knowledge_Base
A19: ServiceNow-style ticket lifecycle | B19: Tickets / Escalation_Cases
A20: SharePoint / VPN / Office / Teams issues | B20: Tickets / Knowledge_Base
A21: Intune compliance monitoring | B21: Tickets / Knowledge_Base
A22: Documentation / SOP / KB creation | B22: Knowledge_Base

Sheet Tickets
A1: Ticket ID | B1: Opened Date | C1: Channel | D1: End User | E1: Region | F1: Department | G1: Device Type | H1: Issue Summary | I1: Category | J1: Subcategory | K1: Primary Tool | L1: Priority | M1: Assigned Group | N1: Escalated | O1: Status | P1: Response Time (hrs) | Q1: Resolution Time (hrs) | R1: SLA Target (hrs) | S1: Within SLA | T1: Root Cause | U1: Resolution Notes | V1: FCR
A2: INC100000 | B2: 46060.625 | C2: Phone | D2: Lavanya Iyer | E2: UK | F2: Sales | G2: Laptop | H2: Need creation of new user account for onboarding | I2: Access | J2: User Creation | K2: Azure AD | L2: High | M2: L1 Service Desk | N2: No | O2: Resolved | P2: 1 | Q2: 3.6 | R2: 4 | S2: =IF(OR(O2="Open",O2="In Progress"),"Pending",IF(Q2<=R2,"Yes","No")) | T2: New hire onboarding | U2: Created account and assigned baseline groups | V2: No
A3: INC100001 | B3: 46067.021 | C3: Chat | D3: Neha Mehta | E3: UK | F3: Sales | G3: Laptop | H3: SharePoint file sync failing on laptop | I3: Software | J3: Sync Issue | K3: SharePoint | L3: Medium | M3: L1 Collaboration Support | N3: Yes | O3: Resolved | P3: 1.4 | Q3: 3.3 | R3: 8 | S3: =IF(OR(O3="Open",O3="In Progress"),"Pending",IF(Q3<=R3,"Yes","No")) | T3: OneDrive sync conflict | U3: Reset sync client and re-linked library | V3: No
A4: INC100002 | B4: 46086.771 | C4: Portal | D4: Priya Kumar | E4: India | F4: IT | G4: Desktop | H4: Need creation of new user account for onboarding | I4: Access | J4: User Creation | K4: Azure AD | L4: High | M4: L1 Service Desk | N4: No | O4: Resolved | P4: 0.3 | Q4: 3.4 | R4: 4 | S4: =IF(OR(O4="Open",O4="In Progress"),"Pending",IF(Q4<=R4,"Yes","No")) | T4: New hire onboarding | U4: Created account and assigned baseline groups | V4: No
A5: INC100003 | B5: 46070.948 | C5: Email | D5: Sanjay Patel | E5: UK | F5: Operations | G5: iPhone | H5: OTP not received for sign-in verification | I5: Access | J5: OTP Failure | K5: Okta | L5: Medium | M5: L1 IAM Support | N5: No | O5: Closed | P5: 1.9 | Q5: 3.5 | R5: 8 | S5: =IF(OR(O5="Open",O5="In Progress"),"Pending",IF(Q5<=R5,"Yes","No")) | T5: Outdated phone number | U5: Updated factor settings and retried verification | V5: Yes
A6: INC100004 | B6: 46070.417 | C6: Email | D6: Priya Rao | E6: India | F6: Operations | G6: iPad | H6: Teams login failure after password change | I6: Software | J6: Teams Login | K6: Microsoft Teams | L6: Low | M6: L1 Service Desk | N6: No | O6: Resolved | P6: 1.6 | Q6: 8.9 | R6: 16 | S6: =IF(OR(O6="Open",O6="In Progress"),"Pending",IF(Q6<=R6,"Yes","No")) | T6: Cached credentials mismatch | U6: Cleared Teams cache and reauthenticated | V6: Yes
A7: INC100005 | B7: 46074.146 | C7: Email | D7: Ravi Reddy | E7: UK | F7: Customer Support | G7: iPad | H7: Outlook not opening on startup | I7: Software | J7: Outlook Issue | K7: Microsoft Office | L7: Low | M7: L1 Service Desk | N7: No | O7: Resolved | P7: 3.8 | Q7: 12.7 | R7: 16 | S7: =IF(OR(O7="Open",O7="In Progress"),"Pending",IF(Q7<=R7,"Yes","No")) | T7: Corrupt Office add-in | U7: Started in safe mode and repaired Office | V7: Yes
A8: INC100006 | B8: 46081.688 | C8: Chat | D8: Manoj Singh | E8: US | F8: Operations | G8: Laptop | H8: Account needs disablement after employee exit | I8: Access | J8: Offboarding | K8: Active Directory | L8: High | M8: L1 Service Desk | N8: Yes | O8: Resolved | P8: 0.8 | Q8: 6.1 | R8: 4 | S8: =IF(OR(O8="Open",O8="In Progress"),"Pending",IF(Q8<=R8,"Yes","No")) | T8: Offboarding request received | U8: Disabled account and removed active sessions | V8: No
A9: INC100007 | B9: 46033.26 | C9: Phone | D9: Tarun Reddy | E9: India | F9: Legal | G9: Thin Client | H9: System performance slow after updates | I9: Hardware | J9: Performance | K9: Windows | L9: Medium | M9: L1 Endpoint Support | N9: Yes | O9: Resolved | P9: 0.4 | Q9: 5.7 | R9: 8 | S9: =IF(OR(O9="Open",O9="In Progress"),"Pending",IF(Q9<=R9,"Yes","No")) | T9: High startup load | U9: Optimized startup items and ran health checks | V9: No
A10: INC100008 | B10: 46064.427 | C10: Portal | D10: Lavanya Verma | E10: US | F10: Procurement | G10: iPhone | H10: Account needs disablement after employee exit | I10: Access | J10: Offboarding | K10: Active Directory | L10: Medium | M10: L1 Service Desk | N10: Yes | O10: Closed | P10: 1.2 | Q10: 9.5 | R10: 8 | S10: =IF(OR(O10="Open",O10="In Progress"),"Pending",IF(Q10<=R10,"Yes","No")) | T10: Offboarding request received | U10: Disabled account and removed active sessions | V10: No
A11: INC100009 | B11: 46078.51 | C11: Phone | D11: Tarun Kumar | E11: India | F11: HR | G11: Desktop | H11: Printer not responding for shared queue | I11: Hardware | J11: Printer Issue | K11: Printer | L11: Medium | M11: L1 Endpoint Support | N11: No | O11: Resolved | P11: 2.3 | Q11: 9.6 | R11: 8 | S11: =IF(OR(O11="Open",O11="In Progress"),"Pending",IF(Q11<=R11,"Yes","No")) | T11: Driver / spooler issue | U11: Restarted spooler and reinstalled driver | V11: No
A12: INC100010 | B12: 46039.615 | C12: Email | D12: Meera Verma | E12: APAC | F12: Customer Support | G12: Laptop | H12: OTP not received for sign-in verification | I12: Access | J12: OTP Failure | K12: Okta | L12: Medium | M12: L1 IAM Support | N12: No | O12: Resolved | P12: 1.7 | Q12: 3.1 | R12: 8 | S12: =IF(OR(O12="Open",O12="In Progress"),"Pending",IF(Q12<=R12,"Yes","No")) | T12: Outdated phone number | U12: Updated factor settings and retried verification | V12: Yes
A13: INC100011 | B13: 46062.688 | C13: Portal | D13: Sneha Kumar | E13: US | F13: Sales | G13: Desktop | H13: Outlook not opening on startup | I13: Software | J13: Outlook Issue | K13: Microsoft Office | L13: Medium | M13: L1 Service Desk | N13: No | O13: Closed | P13: 0.5 | Q13: 3.8 | R13: 8 | S13: =IF(OR(O13="Open",O13="In Progress"),"Pending",IF(Q13<=R13,"Yes","No")) | T13: Corrupt Office add-in | U13: Started in safe mode and repaired Office | V13: No
... A16: INC100014 | B16: 46078.198 | C16: Phone | D16: Manoj Joshi | E16: US | F16: Finance | G16: Laptop | H16: User account locked after failed logins | I16: Login | J16: Account Unlock | K16: Active Directory | L16: High | M16: L1 Service Desk | N16: No | O16: Resolved | P16: 0.8 | Q16: 2.7 | R16: 4 | S16: =IF(OR(O16="Open",O16="In Progress"),"Pending",IF(Q16<=R16,"Yes","No")) | T16: Repeated failed attempts | U16: Unlocked account and advised correct password usage | V16: Yes
A17: INC100015 | B17: 46031.708 | C17: Email | D17: Pooja Jain | E17: UK | F17: Procurement | G17: iPhone | H17: Role-based access required for finance application | I17: Access | J17: Role Assignment | K17: Azure AD | L17: Medium | M17: L1 Service Desk | N17: No | O17: In Progress | P17: 1 | R17: 8 | S17: =IF(OR(O17="Open",O17="In Progress"),"Pending",IF(Q17<=R17,"Yes","No")) | T17: Missing app role assignment | U17: Pending specialist review / awaiting user confirmation | V17: No
A18: INC100016 | B18: 46085.646 | C18: Portal | D18: Sanjay Mehta | E18: India | F18: Finance | G18: Thin Client | H18: SharePoint file sync failing on laptop | I18: Software | J18: Sync Issue | K18: SharePoint | L18: Medium | M18: L1 Collaboration Support | N18: No | O18: Resolved | P18: 0.3 | Q18: 2.2 | R18: 8 | S18: =IF(OR(O18="Open",O18="In Progress"),"Pending",IF(Q18<=R18,"Yes","No")) | T18: OneDrive sync conflict | U18: Reset sync client and re-linked library | V18: Yes
A19: INC100017 | B19: 46052.635 | C19: Chat | D19: Sanjay Rao | E19: UK | F19: Finance | G19: iPhone | H19: Access denied to SharePoint team site | I19: Access | J19: SharePoint Access | K19: SharePoint | L19: Medium | M19: L1 Collaboration Support | N19: No | O19: Resolved | P19: 2.4 | Q19: 9 | R19: 8 | S19: =IF(OR(O19="Open",O19="In Progress"),"Pending",IF(Q19<=R19,"Yes","No")) | T19: Permission group missing | U19: Added user to correct SharePoint group | V19: Yes
A20: INC100018 | B20: 46079.927 | C20: Chat | D20: Ravi Kumar | E20: UK | F20: Legal | G20: Laptop | H20: Software installation blocked on endpoint | I20: Software | J20: Installation Issue | K20: Windows | L20: Medium | M20: L1 Endpoint Support | N20: No | O20: Resolved | P20: 1.6 | Q20: 10 | R20: 8 | S20: =IF(OR(O20="Open",O20="In Progress"),"Pending",IF(Q20<=R20,"Yes","No")) | T20: Admin rights required | U20: Installed package via approved elevated workflow | V20: Yes
A21: INC100019 | B21: 46091.615 | C21: Phone | D21: Lavanya Kapoor | E21: APAC | F21: Finance | G21: Laptop | H21: Software installation blocked on endpoint | I21: Software | J21: Installation Issue | K21: Windows | L21: Medium | M21: L1 Endpoint Support | N21: No | O21: Resolved | P21: 1.4 | Q21: 6.1 | R21: 8 | S21: =IF(OR(O21="Open",O21="In Progress"),"Pending",IF(Q21<=R21,"Yes","No")) | T21: Admin rights required | U21: Installed package via approved elevated workflow | V21: No
A22: INC100020 | B22: 46054.646 | C22: Email | D22: Priya Joshi | E22: UK | F22: Sales | G22: Laptop | H22: Teams login failure after password change | I22: Software | J22: Teams Login | K22: Microsoft Teams | L22: Medium | M22: L1 Service Desk | N22: No | O22: Closed | P22: 2 | Q22: 6.5 | R22: 8 | S22: =IF(OR(O22="Open",O22="In Progress"),"Pending",IF(Q22<=R22,"Yes","No")) | T22: Cached credentials mismatch | U22: Cleared Teams cache and reauthenticated | V22: Yes
A23: INC100021 | B23: 46096.594 | C23: Portal | D23: Pooja Sharma | E23: US | F23: IT | G23: iPhone | H23: Access denied to SharePoint team site | I23: Access | J23: SharePoint Access | K23: SharePoint | L23: High | M23: L1 Collaboration Support | N23: No | O23: Resolved | P23: 0.4 | Q23: 8.4 | R23: 4 | S23: =IF(OR(O23="Open",O23="In Progress"),"Pending",IF(Q23<=R23,"Yes","No")) | T23: Permission group missing | U23: Added user to correct SharePoint group | V23: No
A24: INC100022 | B24: 46098.031 | C24: Phone | D24: Divya Iyer | E24: US | F24: Sales | G24: iPhone | H24: Access denied to SharePoint team site | I24: Access | J24: SharePoint Access | K24: SharePoint | L24: High | M24: L1 Collaboration Support | N24: Yes | O24: Resolved | P24: 0.5 | Q24: 8 | R24: 4 | S24: =IF(OR(O24="Open",O24="In Progress"),"Pending",IF(Q24<=R24,"Yes","No")) | T24: Permission group missing | U24: Added user to correct SharePoint group | V24: No
A25: INC100023 | B25: 46071.823 | C25: Chat | D25: Lavanya Mehta | E25: India | F25: HR | G25: Laptop | H25: New user mailbox access not available | I25: Access | J25: Mailbox Provisioning | K25: Azure AD | L25: Medium | M25: L1 Service Desk | N25: Yes | O25: Closed | P25: 0.2 | Q25: 7 | R25: 8 | S25: =IF(OR(O25="Open",O25="In Progress"),"Pending",IF(Q25<=R25,"Yes","No")) | T25: License sync delay | U25: Verified license assignment and sync completion | V25: No
A26: INC100024 | B26: 46071.958 | C26: Phone | D26: Karthik Joshi | E26: US | F26: Procurement | G26: iPad | H26: Device marked non-compliant in management portal | I26: Compliance | J26: Compliance Alert | K26: Intune | L26: High | M26: L1 Endpoint Support | N26: No | O26: Resolved | P26: 0.7 | Q26: 3.1 | R26: 4 | S26: =IF(OR(O26="Open",O26="In Progress"),"Pending",IF(Q26<=R26,"Yes","No")) | T26: Encryption / policy mismatch | U26: Triggered policy sync and updated compliance state | V26: No
A27: INC100025 | B27: 46065.125 | C27: Chat | D27: Ravi Singh | E27: UK | F27: HR | G27: iPhone | H27: OTP not received for sign-in verification | I27: Access | J27: OTP Failure | K27: Okta | L27: Medium | M27: L1 IAM Support | N27: No | O27: Closed | P27: 1.7 | Q27: 2.9 | R27: 8 | S27: =IF(OR(O27="Open",O27="In Progress"),"Pending",IF(Q27<=R27,"Yes","No")) | T27: Outdated phone number | U27: Updated factor settings and retried verification | V27: Yes
A28: INC100026 | B28: 46085.073 | C28: Phone | D28: Neha Singh | E28: UK | F28: Customer Support | G28: Desktop | H28: OTP not received for sign-in verification | I28: Access | J28: OTP Failure | K28: Okta | L28: Medium | M28: L1 IAM Support | N28: Yes | O28: Closed | P28: 0.6 | Q28: 7.8 | R28: 8 | S28: =IF(OR(O28="Open",O28="In Progress"),"Pending",IF(Q28<=R28,"Yes","No")) | T28: Outdated phone number | U28: Updated factor settings and retried verification | V28: No
A29: INC100027 | B29: 46066.052 | C29: Chat | D29: Manoj Nair | E29: US | F29: HR | G29: Thin Client | H29: Antivirus disabled warning on endpoint | I29: Compliance | J29: Security Alert | K29: Intune | L29: Medium | M29: L1 Endpoint Support | N29: No | O29: Closed | P29: 0.3 | Q29: 6.9 | R29: 8 | S29: =IF(OR(O29="Open",O29="In Progress"),"Pending",IF(Q29<=R29,"Yes","No")) | T29: Protection service stopped | U29: Restarted endpoint protection service and rechecked | V29: No
... A32: INC100030 | B32: 46097.906 | C32: Portal | D32: Lavanya Nair | E32: US | F32: Legal | G32: iPhone | H32: Antivirus disabled warning on endpoint | I32: Compliance | J32: Security Alert | K32: Intune | L32: High | M32: L1 Endpoint Support | N32: No | O32: Resolved | P32: 1 | Q32: 1.6 | R32: 4 | S32: =IF(OR(O32="Open",O32="In Progress"),"Pending",IF(Q32<=R32,"Yes","No")) | T32: Protection service stopped | U32: Restarted endpoint protection service and rechecked | V32: No
A33: INC100031 | B33: 46065.833 | C33: Chat | D33: Ananya Kumar | E33: UK | F33: IT | G33: iPhone | H33: Access denied to SharePoint team site | I33: Access | J33: SharePoint Access | K33: SharePoint | L33: Medium | M33: L1 Collaboration Support | N33: No | O33: Open | P33: 0.7 | R33: 8 | S33: =IF(OR(O33="Open",O33="In Progress"),"Pending",IF(Q33<=R33,"Yes","No")) | T33: Permission group missing | U33: Pending specialist review / awaiting user confirmation | V33: No
A34: INC100032 | B34: 46087.552 | C34: Chat | D34: Arjun Reddy | E34: APAC | F34: Customer Support | G34: iPhone | H34: Access denied to SharePoint team site | I34: Access | J34: SharePoint Access | K34: SharePoint | L34: Medium | M34: L1 Collaboration Support | N34: No | O34: In Progress | P34: 1.6 | R34: 8 | S34: =IF(OR(O34="Open",O34="In Progress"),"Pending",IF(Q34<=R34,"Yes","No")) | T34: Permission group missing | U34: Pending specialist review / awaiting user confirmation | V34: No
A35: INC100033 | B35: 46061.542 | C35: Chat | D35: Tarun Gupta | E35: APAC | F35: Finance | G35: Desktop | H35: OTP not received for sign-in verification | I35: Access | J35: OTP Failure | K35: Okta | L35: Medium | M35: L1 IAM Support | N35: No | O35: Closed | P35: 2.1 | Q35: 6.9 | R35: 8 | S35: =IF(OR(O35="Open",O35="In Progress"),"Pending",IF(Q35<=R35,"Yes","No")) | T35: Outdated phone number | U35: Updated factor settings and retried verification | V35: Yes
A36: INC100034 | B36: 46051.615 | C36: Portal | D36: Isha Sharma | E36: APAC | F36: IT | G36: Desktop | H36: OS outdated and pending critical patches | I36: Compliance | J36: Patch Compliance | K36: Intune | L36: High | M36: L1 Endpoint Support | N36: No | O36: In Progress | P36: 3.2 | R36: 4 | S36: =IF(OR(O36="Open",O36="In Progress"),"Pending",IF(Q36<=R36,"Yes","No")) | T36: Pending update ring | U36: Pending specialist review / awaiting user confirmation | V36: No
A37: INC100035 | B37: 46030.656 | C37: Portal | D37: Tarun Singh | E37: India | F37: HR | G37: Desktop | H37: Unable to join Teams meeting from desktop app | I37: Software | J37: Teams Meeting | K37: Microsoft Teams | L37: Low | M37: L1 Service Desk | N37: Yes | O37: Closed | P37: 0.8 | Q37: 6.4 | R37: 16 | S37: =IF(OR(O37="Open",O37="In Progress"),"Pending",IF(Q37<=R37,"Yes","No")) | T37: Client cache / audio stack issue | U37: Reset Teams app and checked device permissions | V37: No
A38: INC100036 | B38: 46093.281 | C38: Phone | D38: Vikram Verma | E38: APAC | F38: Procurement | G38: iPad | H38: Printer not responding for shared queue | I38: Hardware | J38: Printer Issue | K38: Printer | L38: Low | M38: L1 Endpoint Support | N38: No | O38: Resolved | P38: 3 | Q38: 1.5 | R38: 16 | S38: =IF(OR(O38="Open",O38="In Progress"),"Pending",IF(Q38<=R38,"Yes","No")) | T38: Driver / spooler issue | U38: Restarted spooler and reinstalled driver | V38: Yes
A39: INC100037 | B39: 46049.427 | C39: Email | D39: Aarav Singh | E39: US | F39: Sales | G39: Desktop | H39: User account locked after failed logins | I39: Login | J39: Account Unlock | K39: Active Directory | L39: High | M39: L1 Service Desk | N39: No | O39: Resolved | P39: 0.7 | Q39: 1.4 | R39: 4 | S39: =IF(OR(O39="Open",O39="In Progress"),"Pending",IF(Q39<=R39,"Yes","No")) | T39: Repeated failed attempts | U39: Unlocked account and advised correct password usage | V39: Yes
A40: INC100038 | B40: 46092.125 | C40: Chat | D40: Neha Iyer | E40: India | F40: Finance | G40: Thin Client | H40: Unable to join Teams meeting from desktop app | I40: Software | J40: Teams Meeting | K40: Microsoft Teams | L40: Low | M40: L1 Service Desk | N40: No | O40: Closed | P40: 1.6 | Q40: 19.6 | R40: 16 | S40: =IF(OR(O40="Open",O40="In Progress"),"Pending",IF(Q40<=R40,"Yes","No")) | T40: Client cache / audio stack issue | U40: Reset Teams app and checked device permissions | V40: Yes
A41: INC100039 | B41: 46094.271 | C41: Chat | D41: Nikita Verma | E41: India | F41: Finance | G41: Thin Client | H41: Outlook not opening on startup | I41: Software | J41: Outlook Issue | K41: Microsoft Office | L41: Low | M41: L1 Service Desk | N41: Yes | O41: Closed | P41: 2.7 | Q41: 2.3 | R41: 16 | S41: =IF(OR(O41="Open",O41="In Progress"),"Pending",IF(Q41<=R41,"Yes","No")) | T41: Corrupt Office add-in | U41: Started in safe mode and repaired Office | V41: No
A42: INC100040 | B42: 46037.365 | C42: Portal | D42: Divya Jain | E42: APAC | F42: Operations | G42: Desktop | H42: Device marked non-compliant in management portal | I42: Compliance | J42: Compliance Alert | K42: Intune | L42: Medium | M42: L1 Endpoint Support | N42: Yes | O42: Closed | P42: 1.6 | Q42: 7.8 | R42: 8 | S42: =IF(OR(O42="Open",O42="In Progress"),"Pending",IF(Q42<=R42,"Yes","No")) | T42: Encryption / policy mismatch | U42: Triggered policy sync and updated compliance state | V42: No
A43: INC100041 | B43: 46078.896 | C43: Chat | D43: Ravi Rao | E43: US | F43: HR | G43: iPad | H43: Device marked non-compliant in management portal | I43: Compliance | J43: Compliance Alert | K43: Intune | L43: High | M43: L1 Endpoint Support | N43: No | O43: Resolved | P43: 0.9 | Q43: 2.4 | R43: 4 | S43: =IF(OR(O43="Open",O43="In Progress"),"Pending",IF(Q43<=R43,"Yes","No")) | T43: Encryption / policy mismatch | U43: Triggered policy sync and updated compliance state | V43: No
A44: INC100042 | B44: 46056.052 | C44: Chat | D44: Isha Kumar | E44: UK | F44: Procurement | G44: Desktop | H44: Password reset required after expiry | I44: Login | J44: Password Reset | K44: Active Directory | L44: High | M44: L1 Service Desk | N44: No | O44: Closed | P44: 0.7 | Q44: 2.2 | R44: 4 | S44: =IF(OR(O44="Open",O44="In Progress"),"Pending",IF(Q44<=R44,"Yes","No")) | T44: Password policy expiry | U44: Reset password in AD and confirmed sign-in | V44: No
...

Sheet User_Access_Requests
A1: Request ID | B1: Request Date | C1: Employee Name | D1: Department | E1: Request Type | F1: Tool | G1: Access / Action | H1: Approval Status | I1: Completion Status | J1: Assigned Team | K1: SLA Target (hrs) | L1: Completion Time (hrs) | M1: Within SLA | N1: Notes
A2: REQ20000 | B2: 46064.958 | C2: Vikram Das | D2: HR | E2: Role Change | F2: Azure AD | G2: Assign/remove application role | H2: Approved | I2: Completed | J2: IAM Operations | K2: 8 | L2: 0.9 | M2: =IF(OR(I2="Waiting Approval",I2="In Progress"),"Pending",IF(L2<=K2,"Yes","No")) | N2: Role Change request aligned to Azure AD workflow.
A3: REQ20001 | B3: 46059.708 | C3: Neha Iyer | D3: HR | E3: VPN Access | F3: VPN | G3: Provision VPN access | H3: Approved | I3: Completed | J3: Service Desk | K3: 8 | L3: 6.8 | M3: =IF(OR(I3="Waiting Approval",I3="In Progress"),"Pending",IF(L3<=K3,"Yes","No")) | N3: VPN Access request aligned to VPN workflow.
A4: REQ20002 | B4: 46049.167 | C4: Priya Nair | D4: IT | E4: User Onboarding | F4: Azure AD | G4: Create user account + baseline group membership | H4: Pending | I4: Waiting Approval | J4: IAM Operations | K4: 8 | M4: =IF(OR(I4="Waiting Approval",I4="In Progress"),"Pending",IF(L4<=K4,"Yes","No")) | N4: User Onboarding request aligned to Azure AD workflow.
A5: REQ20003 | B5: 46043.583 | C5: Priya Das | D5: Customer Support | E5: VPN Access | F5: VPN | G5: Provision VPN access | H5: Approved | I5: Completed | J5: Service Desk | K5: 8 | L5: 3 | M5: =IF(OR(I5="Waiting Approval",I5="In Progress"),"Pending",IF(L5<=K5,"Yes","No")) | N5: VPN Access request aligned to VPN workflow.
A6: REQ20004 | B6: 46051.458 | C6: Rahul Singh | D6: IT | E6: Role Change | F6: Azure AD | G6: Assign/remove application role | H6: Approved | I6: Completed | J6: IAM Operations | K6: 8 | L6: 2.3 | M6: =IF(OR(I6="Waiting Approval",I6="In Progress"),"Pending",IF(L6<=K6,"Yes","No")) | N6: Role Change request aligned to Azure AD workflow.
A7: REQ20005 | B7: 46062.542 | C7: Rahul Joshi | D7: Legal | E7: User Onboarding | F7: Azure AD | G7: Create user account + baseline group membership | H7: Approved | I7: Completed | J7: IAM Operations | K7: 8 | L7: 0.6 | M7: =IF(OR(I7="Waiting Approval",I7="In Progress"),"Pending",IF(L7<=K7,"Yes","No")) | N7: User Onboarding request aligned to Azure AD workflow.
A8: REQ20006 | B8: 46053.208 | C8: Tarun Verma | D8: Procurement | E8: SharePoint Access | F8: SharePoint | G8: Add to site permissions group | H8: Approved | I8: In Progress | J8: Collaboration Support | K8: 8 | M8: =IF(OR(I8="Waiting Approval",I8="In Progress"),"Pending",IF(L8<=K8,"Yes","No")) | N8: SharePoint Access request aligned to SharePoint workflow.
A9: REQ20007 | B9: 46078.792 | C9: Isha Verma | D9: Sales | E9: Role Change | F9: Azure AD | G9: Assign/remove application role | H9: Approved | I9: Completed | J9: IAM Operations | K9: 8 | L9: 2.2 | M9: =IF(OR(I9="Waiting Approval",I9="In Progress"),"Pending",IF(L9<=K9,"Yes","No")) | N9: Role Change request aligned to Azure AD workflow.
A10: REQ20008 | B10: 46082.583 | C10: Aarav Mehta | D10: Finance | E10: Role Change | F10: Azure AD | G10: Assign/remove application role | H10: Pending | I10: Waiting Approval | J10: IAM Operations | K10: 8 | M10: =IF(OR(I10="Waiting Approval",I10="In Progress"),"Pending",IF(L10<=K10,"Yes","No")) | N10: Role Change request aligned to Azure AD workflow.
A11: REQ20009 | B11: 46037.167 | C11: Arjun Das | D11: Sales | E11: MFA Enrollment | F11: Okta | G11: Enroll user in MFA factor | H11: Pending | I11: Waiting Approval | J11: IAM Operations | K11: 4 | M11: =IF(OR(I11="Waiting Approval",I11="In Progress"),"Pending",IF(L11<=K11,"Yes","No")) | N11: MFA Enrollment request aligned to Okta workflow.
A12: REQ20010 | B12: 46033.417 | C12: Kiran Kapoor | D12: Procurement | E12: Password Reset | F12: Active Directory | G12: Reset password and verify login | H12: Approved | I12: Completed | J12: Service Desk | K12: 4 | L12: 4.8 | M12: =IF(OR(I12="Waiting Approval",I12="In Progress"),"Pending",IF(L12<=K12,"Yes","No")) | N12: Password Reset request aligned to Active Directory workflow.
A13: REQ20011 | B13: 46088.125 | C13: Divya Nair | D13: HR | E13: Mailbox Enablement | F13: Azure AD | G13: Apply productivity license | H13: Approved | I13: Completed | J13: IAM Operations | K13: 8 | L13: 4.8 | M13: =IF(OR(I13="Waiting Approval",I13="In Progress"),"Pending",IF(L13<=K13,"Yes","No")) | N13: Mailbox Enablement request aligned to Azure AD workflow.
A14: REQ20012 | B14: 46065.417 | C14: Kiran Kumar | D14: Procurement | E14: User Onboarding | F14: Azure AD | G14: Create user account + baseline group membership | H14: Approved | I14: Completed | J14: IAM Operations | K14: 8 | L14: 6.6 | M14: =IF(OR(I14="Waiting Approval",I14="In Progress"),"Pending",IF(L14<=K14,"Yes","No")) | N14: User Onboarding request aligned to Azure AD workflow.
A15: REQ20013 | B15: 46055.458 | C15: Sanjay Iyer | D15: Sales | E15: Role Change | F15: Azure AD | G15: Assign/remove application role | H15: Approved | I15: Completed | J15: IAM Operations | K15: 8 | L15: 1.3 | M15: =IF(OR(I15="Waiting Approval",I15="In Progress"),"Pending",IF(L15<=K15,"Yes","No")) | N15: Role Change request aligned to Azure AD workflow.
A16: REQ20014 | B16: 46042.333 | C16: Sanjay Nair | D16: IT | E16: User Offboarding | F16: Active Directory | G16: Disable account + revoke sessions | H16: Pending | I16: Waiting Approval | J16: IAM Operations | K16: 4 | M16: =IF(OR(I16="Waiting Approval",I16="In Progress"),"Pending",IF(L16<=K16,"Yes","No")) | N16: User Offboarding request aligned to Active Directory workflow.
A17: REQ20015 | B17: 46074.042 | C17: Divya Verma | D17: Sales | E17: User Offboarding | F17: Active Directory | G17: Disable account + revoke sessions | H17: Pending | I17: Waiting Approval | J17: IAM Operations | K17: 4 | M17: =IF(OR(I17="Waiting Approval",I17="In Progress"),"Pending",IF(L17<=K17,"Yes","No")) | N17: User Offboarding request aligned to Active Directory workflow.
A18: REQ20016 | B18: 46067.833 | C18: Vikram Rao | D18: HR | E18: MFA Enrollment | F18: Okta | G18: Enroll user in MFA factor | H18: Approved | I18: Completed | J18: IAM Operations | K18: 4 | L18: 2.8 | M18: =IF(OR(I18="Waiting Approval",I18="In Progress"),"Pending",IF(L18<=K18,"Yes","No")) | N18: MFA Enrollment request aligned to Okta workflow.
A19: REQ20017 | B19: 46046.667 | C19: Ravi Patel | D19: HR | E19: User Onboarding | F19: Azure AD | G19: Create user account + baseline group membership | H19: Approved | I19: Completed | J19: IAM Operations | K19: 8 | L19: 2.7 | M19: =IF(OR(I19="Waiting Approval",I19="In Progress"),"Pending",IF(L19<=K19,"Yes","No")) | N19: User Onboarding request aligned to Azure AD workflow.
A20: REQ20018 | B20: 46030.958 | C20: Karthik Rao | D20: Legal | E20: VPN Access | F20: VPN | G20: Provision VPN access | H20: Approved | I20: Completed | J20: Service Desk | K20: 8 | L20: 5.1 | M20: =IF(OR(I20="Waiting Approval",I20="In Progress"),"Pending",IF(L20<=K20,"Yes","No")) | N20: VPN Access request aligned to VPN workflow.
A21: REQ20019 | B21: 46038.667 | C21: Aarav Sharma | D21: Sales | E21: VPN Access | F21: VPN | G21: Provision VPN access | H21: Approved | I21: Completed | J21: Service Desk | K21: 8 | L21: 5.1 | M21: =IF(OR(I21="Waiting Approval",I21="In Progress"),"Pending",IF(L21<=K21,"Yes","No")) | N21: VPN Access request aligned to VPN workflow.
A22: REQ20020 | B22: 46078 | C22: Tarun Iyer | D22: HR | E22: User Offboarding | F22: Active Directory | G22: Disable account + revoke sessions | H22: Approved | I22: Completed | J22: IAM Operations | K22: 4 | L22: 3.2 | M22: =IF(OR(I22="Waiting Approval",I22="In Progress"),"Pending",IF(L22<=K22,"Yes","No")) | N22: User Offboarding request aligned to Active Directory workflow.
A23: REQ20021 | B23: 46056.625 | C23: Sneha Sharma | D23: Legal | E23: User Offboarding | F23: Active Directory | G23: Disable account + revoke sessions | H23: Approved | I23: Completed | J23: IAM Operations | K23: 4 | L23: 2.9 | M23: =IF(OR(I23="Waiting Approval",I23="In Progress"),"Pending",IF(L23<=K23,"Yes","No")) | N23: User Offboarding request aligned to Active Directory workflow.
A24: REQ20022 | B24: 46030.833 | C24: Karthik Jain | D24: Customer Support | E24: Password Reset | F24: Active Directory | G24: Reset password and verify login | H24: Approved | I24: Completed | J24: Service Desk | K24: 4 | L24: 1.4 | M24: =IF(OR(I24="Waiting Approval",I24="In Progress"),"Pending",IF(L24<=K24,"Yes","No")) | N24: Password Reset request aligned to Active Directory workflow.
A25: REQ20023 | B25: 46031.25 | C25: Nikita Singh | D25: Sales | E25: VPN Access | F25: VPN | G25: Provision VPN access | H25: Approved | I25: In Progress | J25: Service Desk | K25: 8 | M25: =IF(OR(I25="Waiting Approval",I25="In Progress"),"Pending",IF(L25<=K25,"Yes","No")) | N25: VPN Access request aligned to VPN workflow.
A26: REQ20024 | B26: 46075.292 | C26: Isha Sharma | D26: HR | E26: Mailbox Enablement | F26: Azure AD | G26: Apply productivity license | H26: Approved | I26: In Progress | J26: IAM Operations | K26: 8 | M26: =IF(OR(I26="Waiting Approval",I26="In Progress"),"Pending",IF(L26<=K26,"Yes","No")) | N26: Mailbox Enablement request aligned to Azure AD workflow.
A27: REQ20025 | B27: 46064.083 | C27: Arjun Jain | D27: Sales | E27: VPN Access | F27: VPN | G27: Provision VPN access | H27: Approved | I27: In Progress | J27: Service Desk | K27: 8 | M27: =IF(OR(I27="Waiting Approval",I27="In Progress"),"Pending",IF(L27<=K27,"Yes","No")) | N27: VPN Access request aligned to VPN workflow.
A28: REQ20026 | B28: 46069.25 | C28: Lavanya Verma | D28: Legal | E28: Role Change | F28: Azure AD | G28: Assign/remove application role | H28: Approved | I28: Completed | J28: IAM Operations | K28: 8 | L28: 2.8 | M28: =IF(OR(I28="Waiting Approval",I28="In Progress"),"Pending",IF(L28<=K28,"Yes","No")) | N28: Role Change request aligned to Azure AD workflow.
A29: REQ20027 | B29: 46030.833 | C29: Vikram Sharma | D29: Legal | E29: SharePoint Access | F29: SharePoint | G29: Add to site permissions group | H29: Approved | I29: Completed | J29: Collaboration Support | K29: 8 | L29: 5.3 | M29: =IF(OR(I29="Waiting Approval",I29="In Progress"),"Pending",IF(L29<=K29,"Yes","No")) | N29: SharePoint Access request aligned to SharePoint workflow.
A30: REQ20028 | B30: 46073.833 | C30: Priya Verma | D30: Sales | E30: MFA Enrollment | F30: Okta | G30: Enroll user in MFA factor | H30: Pending | I30: Waiting Approval | J30: IAM Operations | K30: 4 | M30: =IF(OR(I30="Waiting Approval",I30="In Progress"),"Pending",IF(L30<=K30,"Yes","No")) | N30: MFA Enrollment request aligned to Okta workflow.
A31: REQ20029 | B31: 46043.125 | C31: Neha Kumar | D31: IT | E31: Role Change | F31: Azure AD | G31: Assign/remove application role | H31: Approved | I31: Completed | J31: IAM Operations | K31: 8 | L31: 4.6 | M31: =IF(OR(I31="Waiting Approval",I31="In Progress"),"Pending",IF(L31<=K31,"Yes","No")) | N31: Role Change request aligned to Azure AD workflow.
A32: REQ20030 | B32: 46076.375 | C32: Arjun Rao | D32: Legal | E32: VPN Access | F32: VPN | G32: Provision VPN access | H32: Approved | I32: Completed | J32: Service Desk | K32: 8 | L32: 2.2 | M32: =IF(OR(I32="Waiting Approval",I32="In Progress"),"Pending",IF(L32<=K32,"Yes","No")) | N32: VPN Access request aligned to VPN workflow.
A33: REQ20031 | B33: 46030 | C33: Manoj Nair | D33: Finance | E33: SharePoint Access | F33: SharePoint | G33: Add to site permissions group | H33: Approved | I33: Completed | J33: Collaboration Support | K33: 8 | L33: 1.8 | M33: =IF(OR(I33="Waiting Approval",I33="In Progress"),"Pending",IF(L33<=K33,"Yes","No")) | N33: SharePoint Access request aligned to SharePoint workflow.
A34: REQ20032 | B34: 46033.375 | C34: Aarav Patel | D34: Operations | E34: Role Change | F34: Azure AD | G34: Assign/remove application role | H34: Approved | I34: Completed | J34: IAM Operations | K34: 8 | L34: 7.4 | M34: =IF(OR(I34="Waiting Approval",I34="In Progress"),"Pending",IF(L34<=K34,"Yes","No")) | N34: Role Change request aligned to Azure AD workflow.
A35: REQ20033 | B35: 46078.333 | C35: Sneha Mehta | D35: Procurement | E35: Mailbox Enablement | F35: Azure AD | G35: Apply productivity license | H35: Approved | I35: Completed | J35: IAM Operations | K35: 8 | L35: 3.7 | M35: =IF(OR(I35="Waiting Approval",I35="In Progress"),"Pending",IF(L35<=K35,"Yes","No")) | N35: Mailbox Enablement request aligned to Azure AD workflow.
A36: REQ20034 | B36: 46083.708 | C36: Ravi Patel | D36: IT | E36: Password Reset | F36: Active Directory | G36: Reset password and verify login | H36: Approved | I36: Completed | J36: Service Desk | K36: 4 | L36: 1.5 | M36: =IF(OR(I36="Waiting Approval",I36="In Progress"),"Pending",IF(L36<=K36,"Yes","No")) | N36: Password Reset request aligned to Active Directory workflow.
A37: REQ20035 | B37: 46090.5 | C37: Aarav Kapoor | D37: Customer Support | E37: VPN Access | F37: VPN | G37: Provision VPN access | H37: Approved | I37: Completed | J37: Service Desk | K37: 8 | L37: 6.5 | M37: =IF(OR(I37="Waiting Approval",I37="In Progress"),"Pending",IF(L37<=K37,"Yes","No")) | N37: VPN Access request aligned to VPN workflow.
A38: REQ20036 | B38: 46082.875 | C38: Tarun Reddy | D38: Legal | E38: SharePoint Access | F38: SharePoint | G38: Add to site permissions group | H38: Approved | I38: Completed | J38: Collaboration Support | K38: 8 | L38: 7.7 | M38: =IF(OR(I38="Waiting Approval",I38="In Progress"),"Pending",IF(L38<=K38,"Yes","No")) | N38: SharePoint Access request aligned to SharePoint workflow.
A39: REQ20037 | B39: 46082.583 | C39: Rahul Rao | D39: IT | E39: VPN Access | F39: VPN | G39: Provision VPN access | H39: Pending | I39: Waiting Approval | J39: Service Desk | K39: 8 | M39: =IF(OR(I39="Waiting Approval",I39="In Progress"),"Pending",IF(L39<=K39,"Yes","No")) | N39: VPN Access request aligned to VPN workflow.
A40: REQ20038 | B40: 46050.958 | C40: Arjun Kumar | D40: HR | E40: User Onboarding | F40: Azure AD | G40: Create user account + baseline group membership | H40: Approved | I40: Completed | J40: IAM Operations | K40: 8 | L40: 0.9 | M40: =IF(OR(I40="Waiting Approval",I40="In Progress"),"Pending",IF(L40<=K40,"Yes","No")) | N40: User Onboarding request aligned to Azure AD workflow.
...

Sheet Escalation_Cases
A1: Ticket ID | B1: Issue Summary | C1: Category | D1: Primary Tool | E1: Priority | F1: Opened Date | G1: Escalated To | H1: Reason for Escalation | I1: Business Impact | J1: Handoff Notes | K1: Current Status
A2: INC100001 | B2: SharePoint file sync failing on laptop | C2: Software | D2: SharePoint | E2: Medium | F2: 46067.021 | G2: L2 Collaboration Team | H2: Issue exceeded L1 troubleshooting scope | I2: Multiple failed authentication attempts affecting productivity | J2: L1 checks completed; shared logs, user impact, and troubleshooting history with L2 Collaboration Team. | K2: Assigned to L2
A3: INC100006 | B3: Account needs disablement after employee exit | C3: Access | D3: Active Directory | E3: High | F3: 46081.688 | G3: L2 IAM Engineering | H3: Compliance state not updating after standard sync | I3: Collaboration and document access interrupted | J3: L1 checks completed; shared logs, user impact, and troubleshooting history with L2 IAM Engineering. | K3: Assigned to L2
A4: INC100007 | B4: System performance slow after updates | C4: Hardware | D4: Windows | E4: Medium | F4: 46033.26 | G4: L2 Endpoint Engineering | H4: Requires backend platform review | I4: Access blocked for payroll / finance processing | J4: L1 checks completed; shared logs, user impact, and troubleshooting history with L2 Endpoint Engineering. | K4: Assigned to L2
A5: INC100008 | B5: Account needs disablement after employee exit | C5: Access | D5: Active Directory | E5: Medium | F5: 46064.427 | G5: L2 IAM Engineering | H5: Compliance state not updating after standard sync | I5: Multiple failed authentication attempts affecting productivity | J5: L1 checks completed; shared logs, user impact, and troubleshooting history with L2 IAM Engineering. | K5: Resolved by L2
A6: INC100022 | B6: Access denied to SharePoint team site | C6: Access | D6: SharePoint | E6: High | F6: 46098.031 | G6: L2 Collaboration Team | H6: Requires backend platform review | I6: User unable to work on business-critical application | J6: L1 checks completed; shared logs, user impact, and troubleshooting history with L2 Collaboration Team. | K6: Under Investigation
A7: INC100023 | B7: New user mailbox access not available | C7: Access | D7: Azure AD | E7: Medium | F7: 46071.823 | G7: L2 IAM Engineering | H7: Policy / configuration change required | I7: Access blocked for payroll / finance processing | J7: L1 checks completed; shared logs, user impact, and troubleshooting history with L2 IAM Engineering. | K7: Resolved by L2
A8: INC100026 | B8: OTP not received for sign-in verification | C8: Access | D8: Okta | E8: Medium | F8: 46085.073 | G8: L2 Identity Platform | H8: Requires backend platform review | I8: Collaboration and document access interrupted | J8: L1 checks completed; shared logs, user impact, and troubleshooting history with L2 Identity Platform. | K8: Awaiting Vendor
A9: INC100028 | B9: Access denied to SharePoint team site | C9: Access | D9: SharePoint | E9: High | F9: 46040.875 | G9: L2 Collaboration Team | H9: Policy / configuration change required | I9: Remote employee unable to connect to corporate resources | J9: L1 checks completed; shared logs, user impact, and troubleshooting history with L2 Collaboration Team. | K9: Under Investigation
A10: INC100035 | B10: Unable to join Teams meeting from desktop app | C10: Software | D10: Microsoft Teams | E10: Low | F10: 46030.656 | G10: L2 Workplace Support | H10: Issue exceeded L1 troubleshooting scope | I10: Multiple failed authentication attempts affecting productivity | J10: L1 checks completed; shared logs, user impact, and troubleshooting history with L2 Workplace Support. | K10: Resolved by L2
A11: INC100039 | B11: Outlook not opening on startup | C11: Software | D11: Microsoft Office | E11: Low | F11: 46094.271 | G11: L2 Workplace Support | H11: Compliance state not updating after standard sync | I11: Access blocked for payroll / finance processing | J11: L1 checks completed; shared logs, user impact, and troubleshooting history with L2 Workplace Support. | K11: Resolved by L2
A12: INC100040 | B12: Device marked non-compliant in management portal | C12: Compliance | D12: Intune | E12: Medium | F12: 46037.365 | G12: L2 Endpoint Engineering | H12: Compliance state not updating after standard sync | I12: User unable to work on business-critical application | J12: L1 checks completed; shared logs, user impact, and troubleshooting history with L2 Endpoint Engineering. | K12: Assigned to L2
A13: INC100050 | B13: System performance slow after updates | C13: Hardware | D13: Windows | E13: Low | F13: 46052.49 | G13: L2 Endpoint Engineering | H13: Requires backend platform review | I13: Remote employee unable to connect to corporate resources | J13: L1 checks completed; shared logs, user impact, and troubleshooting history with L2 Endpoint Engineering. | K13: Under Investigation
... A39: INC100197 | B39: Device marked non-compliant in management portal | C39: Compliance | D39: Intune | E39: High | F39: 46062.625 | G39: L2 Endpoint Engineering | H39: Compliance state not updating after standard sync | I39: User unable to work on business-critical application | J39: L1 checks completed; shared logs, user impact, and troubleshooting history with L2 Endpoint Engineering. | K39: Assigned to L2

Sheet Knowledge_Base
A1: KB ID | B1: Issue Type | C1: Primary Tool | D1: Symptoms | E1: Troubleshooting Steps | F1: Standard Resolution | G1: Escalate When | H1: Article Owner
A2: KB001 | B2: Password Reset | C2: Active Directory | D2: User cannot sign in after password expiry | E2: Verify identity; unlock if needed; reset password; confirm new sign-in | F2: Reset password and document action in ticket | G2: Account still fails after verified reset | H2: L1 Service Desk
A3: KB002 | B3: Account Unlock | C3: Active Directory | D3: Multiple failed attempts trigger lockout | E3: Check lock status; verify user identity; unlock; advise on correct credentials | F3: Account unlocked and access restored | G3: Repeated lockouts suggest sync / brute-force issue | H3: L1 Service Desk
A4: KB003 | B4: VPN Access Failure | C4: VPN | D4: Remote user cannot connect to corporate network | E4: Verify internet; confirm VPN entitlement; refresh client profile; retry login | F4: VPN profile corrected and access restored | G4: Tunnel fails after profile reset | H4: L1 Service Desk
A5: KB004 | B5: Outlook Not Opening | C5: Microsoft Office | D5: Outlook crashes or hangs on launch | E5: Open in safe mode; disable add-ins; repair Office; recreate profile if needed | F5: Office repaired / add-ins isolated | G5: Mailbox corruption or persistent profile issue | H5: L1 Workplace Support
A6: KB005 | B6: Teams Login Failure | C6: Microsoft Teams | D6: User unable to sign in to Teams | E6: Confirm password works in browser; clear Teams cache; reauthenticate | F6: Teams cache reset and session restored | G6: SSO or tenant issue persists | H6: L1 Workplace Support
A7: KB006 | B7: MFA Push Not Received | C7: Okta | D7: User does not receive MFA challenge | E7: Check device enrollment; confirm internet; re-enroll factor | F7: MFA factor re-enrolled successfully | G7: Identity policy / device binding issue remains | H7: L1 IAM Support
A8: KB007 | B8: OTP Not Received | C8: Okta | D8: SMS or email OTP not delivered | E8: Validate registered factor details; resend challenge; update phone/email | F8: Correct factor updated and OTP received | G8: Downstream provider issue or policy block | H8: L1 IAM Support
A9: KB008 | B9: SharePoint Access Denied | C9: SharePoint | D9: Permission denied while opening team site | E9: Check site group membership; validate request approval; add correct permissions | F9: User added to approved SharePoint group | G9: Broken inheritance or advanced permission issue | H9: L1 Collaboration Support
A10: KB009 | B10: Software Installation Failed | C10: Windows | D10: Approved application fails to install | E10: Check endpoint compliance; verify package source; run with elevated rights | F10: Application installed via approved method | G10: Packaging defect or admin deployment required | H10: L1 Endpoint Support
A11: KB010 | B11: Slow System Performance | C11: Windows | D11: Laptop slow, delayed logon, high startup usage | E11: Review startup apps; clear temp files; restart; run health checks | F11: Performance improved after optimization | G11: Disk / memory / hardware fault suspected | H11: L1 Endpoint Support
A12: KB011 | B12: Printer Not Working | C12: Printer | D12: Shared printer offline or jobs stuck | E12: Restart spooler; re-add printer; update driver; test print | F12: Printer restored and queue cleared | G12: Network print server or hardware fault | H12: L1 Endpoint Support
... A23: KB022 | B23: Account Lock Recurrence | C23: Active Directory | D23: User repeatedly locks out after password change | E23: Check cached credentials on mobile / apps; sign out stale sessions | F23: Stale sessions removed and issue stabilized | G23: Unknown source continues auth attempts | H23: L1 Service Desk

Sheet SLA_Dashboard
A1: Service Desk KPI Dashboard
A3: Total Tickets | B3: =COUNTA(Tickets!A:A)-1 | D3: Priority Mix | G3: Status Mix
A4: Resolved / Closed Tickets | B4: =COUNTIF(Tickets!O:O,"Resolved")+COUNTIF(Tickets!O:O,"Closed") | D4: High | E4: =COUNTIF(Tickets!L:L,"High") | G4: Resolved | H4: =COUNTIF(Tickets!O:O,"Resolved")
A5: Open / In Progress Tickets | B5: =COUNTIF(Tickets!O:O,"Open")+COUNTIF(Tickets!O:O,"In Progress") | D5: Medium | E5: =COUNTIF(Tickets!L:L,"Medium") | G5: Closed | H5: =COUNTIF(Tickets!O:O,"Closed")
A6: Escalated Tickets | B6: =COUNTIF(Tickets!N:N,"Yes") | D6: Low | E6: =COUNTIF(Tickets!L:L,"Low") | G6: Open | H6: =COUNTIF(Tickets!O:O,"Open")
A7: Tickets Within SLA | B7: =COUNTIF(Tickets!S:S,"Yes") | G7: In Progress | H7: =COUNTIF(Tickets!O:O,"In Progress")
A8: SLA Compliance % | B8: =IF(B6=0,0,B7/B3) | D8: Category Mix
A9: First Contact Resolution % | B9: =IF(B3=0,0,COUNTIF(Tickets!V:V,"Yes")/B3) | D9: Login | E9: =COUNTIF(Tickets!I:I,"Login")
A10: Average Response Time (hrs) | B10: =AVERAGE(Tickets!P:P) | D10: Access | E10: =COUNTIF(Tickets!I:I,"Access")
A11: Average Resolution Time (hrs) | B11: =AVERAGE(Tickets!Q:Q) | D11: Software | E11: =COUNTIF(Tickets!I:I,"Software")
D12: Hardware | E12: =COUNTIF(Tickets!I:I,"Hardware")
D13: Compliance | E13: =COUNTIF(Tickets!I:I,"Compliance")
